[INFO]: Running file ~/main/app.py:
[ERROR]: Error in main process
Traceback (most recent call last):
  File "app.py", line 72, in <module>
    getInfo()
  File "app.py", line 33, in getInfo
    if (inp.len() < 3 or inp.len() > 5):
AttributeError: 'list' object has no attribute 'len'
[INFO]: Running file ~/main/app.py:
[INFO]: Running file ~/main/app.py:
[ERROR]: Could not parse input
Traceback (most recent call last):
  File "app.py", line 52, in getInfo
    url = str(url[0])
UnboundLocalError: local variable 'url' referenced before assignment
[INFO]: Running file ~/main/app.py:
[ERROR]: Could not parse input
Traceback (most recent call last):
  File "app.py", line 35, in getInfo
    url = str(url[0])
UnboundLocalError: local variable 'url' referenced before assignment
[INFO]: Running file ~/main/app.py:
[INFO]: Running file ~/main/app.py:
[INFO]: Running file ~/main/app.py:
[INFO]: Running file ~/main/app.py:
[INFO]: app.py started:
[INFO]: getInfo started...
[INFO]: Audio mediatype selected...
[DEBUG]: getAudio started:
[ERROR]: Error in main process
Traceback (most recent call last):
  File "app.py", line 65, in getAudio
    jsonfile = open('./JSON/%s.json' % medianame, 'w')
FileNotFoundError: [Errno 2] No such file or directory: './JSON/sdfa.json'

During handling of the above exception, another exception occurred:

Traceback (most recent call last):
  File "app.py", line 83, in getInfo
    getAudio()
  File "app.py", line 71, in getAudio
    log.Exception('Error in getYoutube:')
AttributeError: 'Logger' object has no attribute 'Exception'

During handling of the above exception, another exception occurred:

Traceback (most recent call last):
  File "app.py", line 104, in <module>
    getInfo()
  File "app.py", line 97, in getInfo
    log.Exception('getInfo error:')
AttributeError: 'Logger' object has no attribute 'Exception'
[INFO]: Running file ~/main/app.py:
[INFO]: app.py started:
[INFO]: getInfo started...
[INFO]: Audio mediatype selected...
[DEBUG]: getAudio started:
[ERROR]: getInfo error:
Traceback (most recent call last):
  File "app.py", line 65, in getAudio
    jsonfile = open('./JSON/%s.json' % medianame, 'w')
FileNotFoundError: [Errno 2] No such file or directory: './JSON/fdafad.json'

During handling of the above exception, another exception occurred:

Traceback (most recent call last):
  File "app.py", line 83, in getInfo
    getAudio()
  File "app.py", line 71, in getAudio
    log.Exception('Error in getYoutube:')
AttributeError: 'Logger' object has no attribute 'Exception'
[INFO]: getInfo started...
[INFO]: Running file ~/main/app.py:
[INFO]: app.py started:
[INFO]: getInfo started...
[INFO]: %s is not a valid media type...
[INFO]: getInfo started...
[INFO]: Audio mediatype selected...
[DEBUG]: getAudio started:
[ERROR]: Error in getYoutube:
Traceback (most recent call last):
  File "app.py", line 65, in getAudio
    jsonfile = open('./JSON/%s.json' % medianame, 'w')
FileNotFoundError: [Errno 2] No such file or directory: './JSON/fdafda.json'
[INFO]: Running file ~/main/app.py:
[INFO]: app.py started:
[INFO]: getInfo started...
[INFO]: Audio mediatype selected...
[DEBUG]: getAudio started:
[ERROR]: Error in getYoutube:
Traceback (most recent call last):
  File "app.py", line 65, in getAudio
    jsonfile = open('./JSON/%s.json' % medianame, 'w+')
FileNotFoundError: [Errno 2] No such file or directory: './JSON/fadff.json'
[INFO]: Running file ~/main/app.py:
[INFO]: app.py started:
[INFO]: getInfo started...
[INFO]: Audio mediatype selected...
[DEBUG]: getAudio started:
[ERROR]: Error in getYoutube:
Traceback (most recent call last):
  File "app.py", line 67, in getAudio
    xml = requests.get(link).text
  File "/usr/local/lib/python3.5/dist-packages/requests/api.py", line 75, in get
    return request('get', url, params=params, **kwargs)
  File "/usr/local/lib/python3.5/dist-packages/requests/api.py", line 60, in request
    return session.request(method=method, url=url, **kwargs)
  File "/usr/local/lib/python3.5/dist-packages/requests/sessions.py", line 519, in request
    prep = self.prepare_request(req)
  File "/usr/local/lib/python3.5/dist-packages/requests/sessions.py", line 462, in prepare_request
    hooks=merge_hooks(request.hooks, self.hooks),
  File "/usr/local/lib/python3.5/dist-packages/requests/models.py", line 313, in prepare
    self.prepare_url(url, params)
  File "/usr/local/lib/python3.5/dist-packages/requests/models.py", line 387, in prepare_url
    raise MissingSchema(error)
requests.exceptions.MissingSchema: Invalid URL 'fdd': No schema supplied. Perhaps you meant http://fdd?
